[2022-09-01 22:26:54,226] Executing: "/bin/git init /var/localrepo -b main".
[2022-09-01 22:26:54,230] Process "/bin/git init /var/localrepo -b main" failed.
[2022-09-01 22:27:16,581] Executing: "/bin/git init /var/localrepo -b main".
[2022-09-01 22:27:16,585] Process "/bin/git init /var/localrepo -b main" failed.
[2022-09-01 22:27:58,739] Executing: "/bin/git init /var/localrepo -b main".
[2022-09-01 22:27:58,742] Process "/bin/git init /var/localrepo -b main" failed.
[2022-09-01 22:27:58,742] Directory '/var/localrepo' already exists!
[2022-09-01 22:28:23,232] Executing: "/bin/git init /var/localrepo -b main".
[2022-09-01 22:28:23,240] Process "/bin/git init /var/localrepo -b main" returned (0)
[2022-09-01 22:28:23,240] Directory '/var/localrepo' already exists!
[2022-09-01 22:28:40,440] Executing: "/bin/git init /var/localrepo -b main".
[2022-09-01 22:28:40,447] Process "/bin/git init /var/localrepo -b main" returned (0)
[2022-09-01 22:28:40,447] Directory '/var/localrepo' already exists!
[2022-09-01 22:29:11,075] Executing: "/bin/git init ~/localrepo -b main".
[2022-09-01 22:29:11,084] Process "/bin/git init ~/localrepo -b main" returned (0)
[2022-09-01 22:29:11,084] Directory '~/localrepo' already exists!
[2022-09-01 22:29:11,085] Executing: "/bin/git remote add repository git@github.com:GoodDay-lab/testing.git".
[2022-09-01 22:29:11,094] Process "/bin/git remote add repository git@github.com:GoodDay-lab/testing.git" returned (0)
[2022-09-01 22:29:11,094] Executing: "/bin/git pull repository main --rebase=true --no-edit --no-commit".
[2022-09-01 22:29:11,098] Process "/bin/git pull repository main --rebase=true --no-edit --no-commit" failed.
[2022-09-01 22:29:11,098] Executing: "/bin/git remote add repository2 git@github.com:GoodDay-lab/testing2.git".
[2022-09-01 22:29:11,103] Process "/bin/git remote add repository2 git@github.com:GoodDay-lab/testing2.git" returned (0)
[2022-09-01 22:29:11,103] Executing: "/bin/git pull repository2 main --rebase=true --no-edit --no-commit".
[2022-09-01 22:29:11,108] Process "/bin/git pull repository2 main --rebase=true --no-edit --no-commit" failed.
[2022-09-01 22:29:11,110]  * Running on http://127.0.0.1:9000 (Press CTRL+C to quit)
[2022-09-01 22:29:38,384] Executing: "/bin/git init ~/localrepo -b main".
[2022-09-01 22:29:38,390] Process "/bin/git init ~/localrepo -b main" returned (0)
[2022-09-01 22:29:38,391] Directory '~/localrepo' already exists!
[2022-09-01 22:29:38,392] Executing: "/bin/git remote add repository git@github.com:GoodDay-lab/testing.git".
[2022-09-01 22:29:38,394] Process "/bin/git remote add repository git@github.com:GoodDay-lab/testing.git" failed.
[2022-09-01 22:29:38,394] Executing: "/bin/git pull repository main --rebase=true --no-edit --no-commit".
[2022-09-01 22:29:38,398] Process "/bin/git pull repository main --rebase=true --no-edit --no-commit" failed.
[2022-09-01 22:29:38,398] Executing: "/bin/git remote add repository2 git@github.com:GoodDay-lab/testing2.git".
[2022-09-01 22:29:38,400] Process "/bin/git remote add repository2 git@github.com:GoodDay-lab/testing2.git" failed.
[2022-09-01 22:29:38,401] Executing: "/bin/git pull repository2 main --rebase=true --no-edit --no-commit".
[2022-09-01 22:29:38,404] Process "/bin/git pull repository2 main --rebase=true --no-edit --no-commit" failed.
[2022-09-01 22:29:38,406]  * Running on http://127.0.0.1:9000 (Press CTRL+C to quit)
[2022-09-01 22:32:21,310] Executing: "/bin/git init /home/django/localrepo -b main".
[2022-09-01 22:32:21,318] Process "/bin/git init /home/django/localrepo -b main" returned (0)
[2022-09-01 22:32:21,318] Directory '/home/django/localrepo' already exists!
[2022-09-01 22:32:21,319] Executing: "/bin/git remote add repository git@github.com:GoodDay-lab/testing.git".
[2022-09-01 22:32:21,321] Process "/bin/git remote add repository git@github.com:GoodDay-lab/testing.git" failed.
[2022-09-01 22:32:21,322] Executing: "/bin/git pull repository main --rebase=true --no-edit --no-commit".
[2022-09-01 22:32:21,324] Process "/bin/git pull repository main --rebase=true --no-edit --no-commit" failed.
[2022-09-01 22:32:21,324] Executing: "/bin/git remote add repository2 git@github.com:GoodDay-lab/testing2.git".
[2022-09-01 22:32:21,327] Process "/bin/git remote add repository2 git@github.com:GoodDay-lab/testing2.git" failed.
[2022-09-01 22:32:21,327] Executing: "/bin/git pull repository2 main --rebase=true --no-edit --no-commit".
[2022-09-01 22:32:21,329] Process "/bin/git pull repository2 main --rebase=true --no-edit --no-commit" failed.
[2022-09-01 22:32:21,331]  * Running on http://127.0.0.1:9000 (Press CTRL+C to quit)
[2022-09-01 22:33:59,675] Executing: "/bin/git init /home/django/localrepo -b main".
[2022-09-01 22:33:59,681] Process "/bin/git init /home/django/localrepo -b main" returned (0)
[2022-09-01 22:33:59,681] Directory '/home/django/localrepo' already exists!
[2022-09-01 22:35:49,886] Executing: "/bin/git init /home/django/localrepo -b main".
[2022-09-01 22:35:49,893] Process "/bin/git init /home/django/localrepo -b main" returned (0)
[2022-09-01 22:35:49,893] Executing: "/bin/git remote add repository git@github.com:GoodDay-lab/testing.git".
[2022-09-01 22:35:49,904] Process "/bin/git remote add repository git@github.com:GoodDay-lab/testing.git" returned (0)
[2022-09-01 22:35:49,904] Executing: "/bin/git pull repository main --rebase=true --no-edit --no-commit".
[2022-09-01 22:35:51,317] Process "/bin/git pull repository main --rebase=true --no-edit --no-commit" failed.
[2022-09-01 22:35:51,317] Executing: "/bin/git remote add repository2 git@github.com:GoodDay-lab/testing2.git".
[2022-09-01 22:35:51,322] Process "/bin/git remote add repository2 git@github.com:GoodDay-lab/testing2.git" returned (0)
[2022-09-01 22:35:51,322] Executing: "/bin/git pull repository2 main --rebase=true --no-edit --no-commit".
[2022-09-01 22:35:52,676] Process "/bin/git pull repository2 main --rebase=true --no-edit --no-commit" failed.
[2022-09-01 22:35:52,679]  * Running on http://127.0.0.1:9000 (Press CTRL+C to quit)
[2022-09-01 22:38:35,001] Directory '/home/django/localrepo' already exists!
[2022-09-01 22:38:35,002] Executing: "/bin/git init /home/django/localrepo -b main".
[2022-09-01 22:38:35,009] Process "/bin/git init /home/django/localrepo -b main" returned (0)
[2022-09-01 22:38:35,010] Executing: "/bin/git remote add repository git@github.com:GoodDay-lab/testing.git".
[2022-09-01 22:38:35,025] Process "/bin/git remote add repository git@github.com:GoodDay-lab/testing.git" returned (0)
[2022-09-01 22:38:35,025] Executing: "/bin/git pull repository main --rebase=true --no-edit --no-commit".
[2022-09-01 22:38:36,384] Process "/bin/git pull repository main --rebase=true --no-edit --no-commit" failed.
[2022-09-01 22:38:36,385] Executing: "/bin/git remote add repository2 git@github.com:GoodDay-lab/testing2.git".
[2022-09-01 22:38:36,390] Process "/bin/git remote add repository2 git@github.com:GoodDay-lab/testing2.git" returned (0)
[2022-09-01 22:38:36,391] Executing: "/bin/git pull repository2 main --rebase=true --no-edit --no-commit".
[2022-09-01 22:38:37,722] Process "/bin/git pull repository2 main --rebase=true --no-edit --no-commit" failed.
[2022-09-01 22:38:37,727]  * Running on http://127.0.0.1:9000 (Press CTRL+C to quit)
[2022-09-01 22:46:00,948] 127.0.0.1 - - [01/Sep/2022 22:46:00] "POST / HTTP/1.1" 200 -
[2022-09-01 22:46:12,160] 127.0.0.1 - - [01/Sep/2022 22:46:12] "POST / HTTP/1.1" 200 -
[2022-09-01 22:46:38,689] Exception on / [POST]
Traceback (most recent call last):
  File "/home/django/opensource/GithubBot-MultiBranches/venv/lib/python3.10/site-packages/flask/app.py", line 2077, in wsgi_app
    response = self.full_dispatch_request()
  File "/home/django/opensource/GithubBot-MultiBranches/venv/lib/python3.10/site-packages/flask/app.py", line 1525, in full_dispatch_request
    rv = self.handle_user_exception(e)
  File "/home/django/opensource/GithubBot-MultiBranches/venv/lib/python3.10/site-packages/flask/app.py", line 1523, in full_dispatch_request
    rv = self.dispatch_request()
  File "/home/django/opensource/GithubBot-MultiBranches/venv/lib/python3.10/site-packages/flask/app.py", line 1509, in dispatch_request
    return self.ensure_sync(self.view_functions[rule.endpoint])(**req.view_args)
  File "/home/django/opensource/GithubBot-MultiBranches/main.py", line 82, in general
    section, repository = get_repository_config(payload)
  File "/home/django/opensource/GithubBot-MultiBranches/main.py", line 68, in get_repository_config
    protocol = get_protocol_name(conf["url"])
  File "/usr/lib/python3.10/configparser.py", line 1258, in __getitem__
    raise KeyError(key)
KeyError: 'url'
[2022-09-01 22:46:38,690] 127.0.0.1 - - [01/Sep/2022 22:46:38] "[35m[1mPOST / HTTP/1.1[0m" 500 -
[2022-09-01 22:47:11,142] Exception on / [POST]
Traceback (most recent call last):
  File "/home/django/opensource/GithubBot-MultiBranches/venv/lib/python3.10/site-packages/flask/app.py", line 2077, in wsgi_app
    response = self.full_dispatch_request()
  File "/home/django/opensource/GithubBot-MultiBranches/venv/lib/python3.10/site-packages/flask/app.py", line 1525, in full_dispatch_request
    rv = self.handle_user_exception(e)
  File "/home/django/opensource/GithubBot-MultiBranches/venv/lib/python3.10/site-packages/flask/app.py", line 1523, in full_dispatch_request
    rv = self.dispatch_request()
  File "/home/django/opensource/GithubBot-MultiBranches/venv/lib/python3.10/site-packages/flask/app.py", line 1509, in dispatch_request
    return self.ensure_sync(self.view_functions[rule.endpoint])(**req.view_args)
  File "/home/django/opensource/GithubBot-MultiBranches/main.py", line 82, in general
    section, repository = get_repository_config(payload)
  File "/home/django/opensource/GithubBot-MultiBranches/main.py", line 68, in get_repository_config
    protocol = get_protocol_name(conf["url"])
  File "/usr/lib/python3.10/configparser.py", line 1258, in __getitem__
    raise KeyError(key)
KeyError: 'url'
[2022-09-01 22:47:11,143] 127.0.0.1 - - [01/Sep/2022 22:47:11] "[35m[1mPOST / HTTP/1.1[0m" 500 -
[2022-09-01 22:50:29,156] Executing: "/bin/git init /home/django/localrepo -b main".
[2022-09-01 22:50:29,163] Process "/bin/git init /home/django/localrepo -b main" returned (0)
[2022-09-01 22:50:29,164] Executing: "/bin/git remote add repository git@github.com:GoodDay-lab/testing.git".
[2022-09-01 22:50:29,174] Process "/bin/git remote add repository git@github.com:GoodDay-lab/testing.git" returned (0)
[2022-09-01 22:50:29,174] Executing: "/bin/git pull repository main --rebase=true --no-edit --no-commit".
[2022-09-01 22:50:32,206] Process "/bin/git pull repository main --rebase=true --no-edit --no-commit" returned (0)
[2022-09-01 22:50:32,207] Executing: "/bin/git remote add repository2 git@github.com:GoodDay-lab/testing2.git".
[2022-09-01 22:50:32,213] Process "/bin/git remote add repository2 git@github.com:GoodDay-lab/testing2.git" returned (0)
[2022-09-01 22:50:32,213] Executing: "/bin/git pull repository2 main --rebase=true --no-edit --no-commit".
[2022-09-01 22:50:34,940] Process "/bin/git pull repository2 main --rebase=true --no-edit --no-commit" returned (0)
[2022-09-01 22:50:34,943]  * Running on http://127.0.0.1:9000 (Press CTRL+C to quit)
[2022-09-01 22:52:27,318] Exception on / [POST]
Traceback (most recent call last):
  File "/home/django/opensource/GithubBot-MultiBranches/venv/lib/python3.10/site-packages/flask/app.py", line 2077, in wsgi_app
    response = self.full_dispatch_request()
  File "/home/django/opensource/GithubBot-MultiBranches/venv/lib/python3.10/site-packages/flask/app.py", line 1525, in full_dispatch_request
    rv = self.handle_user_exception(e)
  File "/home/django/opensource/GithubBot-MultiBranches/venv/lib/python3.10/site-packages/flask/app.py", line 1523, in full_dispatch_request
    rv = self.dispatch_request()
  File "/home/django/opensource/GithubBot-MultiBranches/venv/lib/python3.10/site-packages/flask/app.py", line 1509, in dispatch_request
    return self.ensure_sync(self.view_functions[rule.endpoint])(**req.view_args)
  File "/home/django/opensource/GithubBot-MultiBranches/main.py", line 82, in general
    section, repository = get_repository_config(payload)
  File "/home/django/opensource/GithubBot-MultiBranches/main.py", line 68, in get_repository_config
    protocol = get_protocol_name(conf["url"])
  File "/usr/lib/python3.10/configparser.py", line 1258, in __getitem__
    raise KeyError(key)
KeyError: 'url'
[2022-09-01 22:52:27,320] 127.0.0.1 - - [01/Sep/2022 22:52:27] "[35m[1mPOST / HTTP/1.1[0m" 500 -
[2022-09-01 22:55:24,469] Directory '/home/django/localrepo' already exists!
[2022-09-01 22:55:24,471] Executing: "/bin/git init /home/django/localrepo -b main".
[2022-09-01 22:55:24,483] Process "/bin/git init /home/django/localrepo -b main" returned (0)
[2022-09-01 22:55:24,483] Executing: "/bin/git remote add repository git@github.com:GoodDay-lab/testing.git".
[2022-09-01 22:55:24,487] Process "/bin/git remote add repository git@github.com:GoodDay-lab/testing.git" returned (0)
[2022-09-01 22:55:24,487] Executing: "/bin/git pull repository main --rebase=true --no-edit --no-commit".
[2022-09-01 22:55:27,153] Process "/bin/git pull repository main --rebase=true --no-edit --no-commit" returned (0)
[2022-09-01 22:55:27,153] Executing: "/bin/git remote add repository2 git@github.com:GoodDay-lab/testing2.git".
[2022-09-01 22:55:27,158] Process "/bin/git remote add repository2 git@github.com:GoodDay-lab/testing2.git" returned (0)
[2022-09-01 22:55:27,159] Executing: "/bin/git pull repository2 main --rebase=true --no-edit --no-commit".
[2022-09-01 22:55:30,561] Process "/bin/git pull repository2 main --rebase=true --no-edit --no-commit" returned (0)
[2022-09-01 22:55:30,566]  * Running on http://127.0.0.1:9000 (Press CTRL+C to quit)
[2022-09-01 22:58:30,455] Exception on / [POST]
Traceback (most recent call last):
  File "/home/django/opensource/GithubBot-MultiBranches/venv/lib/python3.10/site-packages/flask/app.py", line 2077, in wsgi_app
    response = self.full_dispatch_request()
  File "/home/django/opensource/GithubBot-MultiBranches/venv/lib/python3.10/site-packages/flask/app.py", line 1525, in full_dispatch_request
    rv = self.handle_user_exception(e)
  File "/home/django/opensource/GithubBot-MultiBranches/venv/lib/python3.10/site-packages/flask/app.py", line 1523, in full_dispatch_request
    rv = self.dispatch_request()
  File "/home/django/opensource/GithubBot-MultiBranches/venv/lib/python3.10/site-packages/flask/app.py", line 1509, in dispatch_request
    return self.ensure_sync(self.view_functions[rule.endpoint])(**req.view_args)
  File "/home/django/opensource/GithubBot-MultiBranches/main.py", line 84, in general
    section, repository = get_repository_config(payload)
  File "/home/django/opensource/GithubBot-MultiBranches/main.py", line 70, in get_repository_config
    protocol = get_protocol_name(conf["url"])
  File "/usr/lib/python3.10/configparser.py", line 1258, in __getitem__
    raise KeyError(key)
KeyError: 'url'
[2022-09-01 22:58:30,456] 127.0.0.1 - - [01/Sep/2022 22:58:30] "[35m[1mPOST / HTTP/1.1[0m" 500 -
[2022-09-01 23:00:12,288] Directory '/home/django/localrepo' already exists!
[2022-09-01 23:00:12,290] Executing: "/bin/git init /home/django/localrepo -b main".
[2022-09-01 23:00:12,297] Process "/bin/git init /home/django/localrepo -b main" returned (0)
[2022-09-01 23:00:12,298] Executing: "/bin/git remote add repository git@github.com:GoodDay-lab/testing.git".
[2022-09-01 23:00:12,309] Process "/bin/git remote add repository git@github.com:GoodDay-lab/testing.git" returned (0)
[2022-09-01 23:00:12,309] Executing: "/bin/git pull repository main --rebase=true --no-edit --no-commit".
[2022-09-01 23:00:15,344] Process "/bin/git pull repository main --rebase=true --no-edit --no-commit" returned (0)
[2022-09-01 23:00:15,344] Executing: "/bin/git remote add repository2 git@github.com:GoodDay-lab/testing2.git".
[2022-09-01 23:00:15,350] Process "/bin/git remote add repository2 git@github.com:GoodDay-lab/testing2.git" returned (0)
[2022-09-01 23:00:15,350] Executing: "/bin/git pull repository2 main --rebase=true --no-edit --no-commit".
[2022-09-01 23:00:18,068] Process "/bin/git pull repository2 main --rebase=true --no-edit --no-commit" returned (0)
[2022-09-01 23:00:18,072]  * Running on http://127.0.0.1:9000 (Press CTRL+C to quit)
[2022-09-01 23:00:34,462] Exception on / [POST]
Traceback (most recent call last):
  File "/home/django/opensource/GithubBot-MultiBranches/venv/lib/python3.10/site-packages/flask/app.py", line 2077, in wsgi_app
    response = self.full_dispatch_request()
  File "/home/django/opensource/GithubBot-MultiBranches/venv/lib/python3.10/site-packages/flask/app.py", line 1525, in full_dispatch_request
    rv = self.handle_user_exception(e)
  File "/home/django/opensource/GithubBot-MultiBranches/venv/lib/python3.10/site-packages/flask/app.py", line 1523, in full_dispatch_request
    rv = self.dispatch_request()
  File "/home/django/opensource/GithubBot-MultiBranches/venv/lib/python3.10/site-packages/flask/app.py", line 1509, in dispatch_request
    return self.ensure_sync(self.view_functions[rule.endpoint])(**req.view_args)
  File "/home/django/opensource/GithubBot-MultiBranches/main.py", line 85, in general
    section, repository = get_repository_config(payload)
  File "/home/django/opensource/GithubBot-MultiBranches/main.py", line 71, in get_repository_config
    protocol = get_protocol_name(conf["url"])
  File "/usr/lib/python3.10/configparser.py", line 1258, in __getitem__
    raise KeyError(key)
KeyError: 'url'
[2022-09-01 23:00:34,464] 127.0.0.1 - - [01/Sep/2022 23:00:34] "[35m[1mPOST / HTTP/1.1[0m" 500 -
[2022-09-01 23:01:14,147] Directory '/home/django/localrepo' already exists!
[2022-09-01 23:01:14,150] Executing: "/bin/git init /home/django/localrepo -b main".
[2022-09-01 23:01:14,158] Process "/bin/git init /home/django/localrepo -b main" returned (0)
[2022-09-01 23:01:14,158] Executing: "/bin/git remote add repository git@github.com:GoodDay-lab/testing.git".
[2022-09-01 23:01:14,168] Process "/bin/git remote add repository git@github.com:GoodDay-lab/testing.git" returned (0)
[2022-09-01 23:01:14,168] Executing: "/bin/git pull repository main --rebase=true --no-edit --no-commit".
[2022-09-01 23:01:16,808] Process "/bin/git pull repository main --rebase=true --no-edit --no-commit" returned (0)
[2022-09-01 23:01:16,808] Executing: "/bin/git remote add repository2 git@github.com:GoodDay-lab/testing2.git".
[2022-09-01 23:01:16,812] Process "/bin/git remote add repository2 git@github.com:GoodDay-lab/testing2.git" returned (0)
[2022-09-01 23:01:16,812] Executing: "/bin/git pull repository2 main --rebase=true --no-edit --no-commit".
[2022-09-01 23:01:19,207] Process "/bin/git pull repository2 main --rebase=true --no-edit --no-commit" returned (0)
[2022-09-01 23:01:38,134] Executing: "/bin/git init /home/django/localrepo -b main".
[2022-09-01 23:01:38,142] Process "/bin/git init /home/django/localrepo -b main" returned (0)
[2022-09-01 23:01:38,143] Executing: "/bin/git remote add repository git@github.com:GoodDay-lab/testing.git".
[2022-09-01 23:01:38,153] Process "/bin/git remote add repository git@github.com:GoodDay-lab/testing.git" returned (0)
[2022-09-01 23:01:38,153] Executing: "/bin/git pull repository main --rebase=true --no-edit --no-commit".
[2022-09-01 23:01:41,263] Process "/bin/git pull repository main --rebase=true --no-edit --no-commit" returned (0)
[2022-09-01 23:01:41,263] Executing: "/bin/git remote add repository2 git@github.com:GoodDay-lab/testing2.git".
[2022-09-01 23:01:41,269] Process "/bin/git remote add repository2 git@github.com:GoodDay-lab/testing2.git" returned (0)
[2022-09-01 23:01:41,269] Executing: "/bin/git pull repository2 main --rebase=true --no-edit --no-commit".
[2022-09-01 23:01:43,771] Process "/bin/git pull repository2 main --rebase=true --no-edit --no-commit" returned (0)
[2022-09-01 23:01:43,775]  * Running on http://127.0.0.1:9000 (Press CTRL+C to quit)
[2022-09-01 23:01:54,986] Exception on / [POST]
Traceback (most recent call last):
  File "/home/django/opensource/GithubBot-MultiBranches/venv/lib/python3.10/site-packages/flask/app.py", line 2077, in wsgi_app
    response = self.full_dispatch_request()
  File "/home/django/opensource/GithubBot-MultiBranches/venv/lib/python3.10/site-packages/flask/app.py", line 1525, in full_dispatch_request
    rv = self.handle_user_exception(e)
  File "/home/django/opensource/GithubBot-MultiBranches/venv/lib/python3.10/site-packages/flask/app.py", line 1523, in full_dispatch_request
    rv = self.dispatch_request()
  File "/home/django/opensource/GithubBot-MultiBranches/venv/lib/python3.10/site-packages/flask/app.py", line 1509, in dispatch_request
    return self.ensure_sync(self.view_functions[rule.endpoint])(**req.view_args)
  File "/home/django/opensource/GithubBot-MultiBranches/main.py", line 85, in general
    section, repository = get_repository_config(payload)
  File "/home/django/opensource/GithubBot-MultiBranches/main.py", line 71, in get_repository_config
    protocol = get_protocol_name(conf["url"])
  File "/usr/lib/python3.10/configparser.py", line 1258, in __getitem__
    raise KeyError(key)
KeyError: 'url'
[2022-09-01 23:01:54,988] 127.0.0.1 - - [01/Sep/2022 23:01:54] "[35m[1mPOST / HTTP/1.1[0m" 500 -
[2022-09-01 23:02:30,488] Directory '/home/django/localrepo' already exists!
[2022-09-01 23:02:30,490] Executing: "/bin/git init /home/django/localrepo -b main".
[2022-09-01 23:02:30,498] Process "/bin/git init /home/django/localrepo -b main" returned (0)
[2022-09-01 23:02:30,498] Executing: "/bin/git remote add repository git@github.com:GoodDay-lab/testing.git".
[2022-09-01 23:02:30,509] Process "/bin/git remote add repository git@github.com:GoodDay-lab/testing.git" returned (0)
[2022-09-01 23:02:30,509] Executing: "/bin/git pull repository main --rebase=true --no-edit --no-commit".
[2022-09-01 23:02:33,466] Process "/bin/git pull repository main --rebase=true --no-edit --no-commit" returned (0)
[2022-09-01 23:02:33,466] Executing: "/bin/git remote add repository2 git@github.com:GoodDay-lab/testing2.git".
[2022-09-01 23:02:33,471] Process "/bin/git remote add repository2 git@github.com:GoodDay-lab/testing2.git" returned (0)
[2022-09-01 23:02:33,472] Executing: "/bin/git pull repository2 main --rebase=true --no-edit --no-commit".
[2022-09-01 23:02:36,051] Process "/bin/git pull repository2 main --rebase=true --no-edit --no-commit" returned (0)
[2022-09-01 23:02:36,054]  * Running on http://127.0.0.1:9000 (Press CTRL+C to quit)
[2022-09-01 23:02:42,223] Exception on / [POST]
Traceback (most recent call last):
  File "/home/django/opensource/GithubBot-MultiBranches/venv/lib/python3.10/site-packages/flask/app.py", line 2077, in wsgi_app
    response = self.full_dispatch_request()
  File "/home/django/opensource/GithubBot-MultiBranches/venv/lib/python3.10/site-packages/flask/app.py", line 1525, in full_dispatch_request
    rv = self.handle_user_exception(e)
  File "/home/django/opensource/GithubBot-MultiBranches/venv/lib/python3.10/site-packages/flask/app.py", line 1523, in full_dispatch_request
    rv = self.dispatch_request()
  File "/home/django/opensource/GithubBot-MultiBranches/venv/lib/python3.10/site-packages/flask/app.py", line 1509, in dispatch_request
    return self.ensure_sync(self.view_functions[rule.endpoint])(**req.view_args)
  File "/home/django/opensource/GithubBot-MultiBranches/main.py", line 85, in general
    section, repository = get_repository_config(payload)
  File "/home/django/opensource/GithubBot-MultiBranches/main.py", line 71, in get_repository_config
    protocol = get_protocol_name(conf["url"])
  File "/usr/lib/python3.10/configparser.py", line 1258, in __getitem__
    raise KeyError(key)
KeyError: 'url'
[2022-09-01 23:02:42,225] 127.0.0.1 - - [01/Sep/2022 23:02:42] "[35m[1mPOST / HTTP/1.1[0m" 500 -
[2022-09-01 23:03:26,241] Directory '/home/django/localrepo' already exists!
[2022-09-01 23:03:26,244] Executing: "/bin/git init /home/django/localrepo -b main".
[2022-09-01 23:03:26,250] Process "/bin/git init /home/django/localrepo -b main" returned (0)
[2022-09-01 23:03:26,250] Executing: "/bin/git remote add repository git@github.com:GoodDay-lab/testing.git".
[2022-09-01 23:03:26,261] Process "/bin/git remote add repository git@github.com:GoodDay-lab/testing.git" returned (0)
[2022-09-01 23:03:26,261] Executing: "/bin/git pull repository main --rebase=true --no-edit --no-commit".
[2022-09-01 23:03:29,166] Process "/bin/git pull repository main --rebase=true --no-edit --no-commit" returned (0)
[2022-09-01 23:03:29,166] Executing: "/bin/git remote add repository2 git@github.com:GoodDay-lab/testing2.git".
[2022-09-01 23:03:29,171] Process "/bin/git remote add repository2 git@github.com:GoodDay-lab/testing2.git" returned (0)
[2022-09-01 23:03:29,171] Executing: "/bin/git pull repository2 main --rebase=true --no-edit --no-commit".
[2022-09-01 23:03:31,908] Process "/bin/git pull repository2 main --rebase=true --no-edit --no-commit" returned (0)
[2022-09-01 23:03:31,911]  * Running on http://127.0.0.1:9000 (Press CTRL+C to quit)
[2022-09-01 23:03:37,523] Exception on / [POST]
Traceback (most recent call last):
  File "/home/django/opensource/GithubBot-MultiBranches/venv/lib/python3.10/site-packages/flask/app.py", line 2077, in wsgi_app
    response = self.full_dispatch_request()
  File "/home/django/opensource/GithubBot-MultiBranches/venv/lib/python3.10/site-packages/flask/app.py", line 1525, in full_dispatch_request
    rv = self.handle_user_exception(e)
  File "/home/django/opensource/GithubBot-MultiBranches/venv/lib/python3.10/site-packages/flask/app.py", line 1523, in full_dispatch_request
    rv = self.dispatch_request()
  File "/home/django/opensource/GithubBot-MultiBranches/venv/lib/python3.10/site-packages/flask/app.py", line 1509, in dispatch_request
    return self.ensure_sync(self.view_functions[rule.endpoint])(**req.view_args)
  File "/home/django/opensource/GithubBot-MultiBranches/main.py", line 86, in general
    section, repository = get_repository_config(payload)
  File "/home/django/opensource/GithubBot-MultiBranches/main.py", line 73, in get_repository_config
    if (conf["url"] == payload["repository"]["%s_url" % protocol]):
KeyError: 'git@github.com:GoodDay-lab/testing.gi_url'
[2022-09-01 23:03:37,525] 127.0.0.1 - - [01/Sep/2022 23:03:37] "[35m[1mPOST / HTTP/1.1[0m" 500 -
[2022-09-01 23:05:45,755] Directory '/home/django/localrepo' already exists!
[2022-09-01 23:05:45,758] Executing: "/bin/git init /home/django/localrepo -b main".
[2022-09-01 23:05:45,765] Process "/bin/git init /home/django/localrepo -b main" returned (0)
[2022-09-01 23:05:45,765] Executing: "/bin/git remote add repository git@github.com:GoodDay-lab/testing.git".
[2022-09-01 23:05:45,770] Process "/bin/git remote add repository git@github.com:GoodDay-lab/testing.git" returned (0)
[2022-09-01 23:05:45,771] Executing: "/bin/git pull repository main --rebase=true --no-edit --no-commit".
[2022-09-01 23:05:48,581] Process "/bin/git pull repository main --rebase=true --no-edit --no-commit" returned (0)
[2022-09-01 23:05:48,581] Executing: "/bin/git remote add repository2 git@github.com:GoodDay-lab/testing2.git".
[2022-09-01 23:05:48,586] Process "/bin/git remote add repository2 git@github.com:GoodDay-lab/testing2.git" returned (0)
[2022-09-01 23:05:48,586] Executing: "/bin/git pull repository2 main --rebase=true --no-edit --no-commit".
[2022-09-01 23:05:51,339] Process "/bin/git pull repository2 main --rebase=true --no-edit --no-commit" returned (0)
[2022-09-01 23:05:51,343]  * Running on http://127.0.0.1:9000 (Press CTRL+C to quit)
[2022-09-01 23:05:56,442] Exception on / [POST]
Traceback (most recent call last):
  File "/home/django/opensource/GithubBot-MultiBranches/venv/lib/python3.10/site-packages/flask/app.py", line 2077, in wsgi_app
    response = self.full_dispatch_request()
  File "/home/django/opensource/GithubBot-MultiBranches/venv/lib/python3.10/site-packages/flask/app.py", line 1525, in full_dispatch_request
    rv = self.handle_user_exception(e)
  File "/home/django/opensource/GithubBot-MultiBranches/venv/lib/python3.10/site-packages/flask/app.py", line 1523, in full_dispatch_request
    rv = self.dispatch_request()
  File "/home/django/opensource/GithubBot-MultiBranches/venv/lib/python3.10/site-packages/flask/app.py", line 1509, in dispatch_request
    return self.ensure_sync(self.view_functions[rule.endpoint])(**req.view_args)
  File "/home/django/opensource/GithubBot-MultiBranches/main.py", line 88, in general
    section, repository = get_repository_config(payload)
  File "/home/django/opensource/GithubBot-MultiBranches/main.py", line 77, in get_repository_config
    return [section, conf]
NameError: name 'section' is not defined
[2022-09-01 23:05:56,443] 127.0.0.1 - - [01/Sep/2022 23:05:56] "[35m[1mPOST / HTTP/1.1[0m" 500 -
[2022-09-01 23:06:18,060] Directory '/home/django/localrepo' already exists!
[2022-09-01 23:06:18,063] Executing: "/bin/git init /home/django/localrepo -b main".
[2022-09-01 23:06:18,071] Process "/bin/git init /home/django/localrepo -b main" returned (0)
[2022-09-01 23:06:18,071] Executing: "/bin/git remote add repository git@github.com:GoodDay-lab/testing.git".
[2022-09-01 23:06:18,081] Process "/bin/git remote add repository git@github.com:GoodDay-lab/testing.git" returned (0)
[2022-09-01 23:06:18,081] Executing: "/bin/git pull repository main --rebase=true --no-edit --no-commit".
[2022-09-01 23:06:21,026] Process "/bin/git pull repository main --rebase=true --no-edit --no-commit" returned (0)
[2022-09-01 23:06:21,026] Executing: "/bin/git remote add repository2 git@github.com:GoodDay-lab/testing2.git".
[2022-09-01 23:06:21,030] Process "/bin/git remote add repository2 git@github.com:GoodDay-lab/testing2.git" returned (0)
[2022-09-01 23:06:21,031] Executing: "/bin/git pull repository2 main --rebase=true --no-edit --no-commit".
[2022-09-01 23:06:23,779] Process "/bin/git pull repository2 main --rebase=true --no-edit --no-commit" returned (0)
[2022-09-01 23:06:23,784]  * Running on http://127.0.0.1:9000 (Press CTRL+C to quit)
[2022-09-01 23:06:30,624] Executing: "/bin/git pull repository main --no-edit --no-commit".
[2022-09-01 23:06:33,761] Process "/bin/git pull repository main --no-edit --no-commit" returned (0)
[2022-09-01 23:06:33,761] Executing: "/bin/git push repository2 main".
[2022-09-01 23:06:36,654] Process "/bin/git push repository2 main" returned (0)
[2022-09-01 23:06:36,655] Exception on / [POST]
Traceback (most recent call last):
  File "/home/django/opensource/GithubBot-MultiBranches/venv/lib/python3.10/site-packages/flask/app.py", line 2077, in wsgi_app
    response = self.full_dispatch_request()
  File "/home/django/opensource/GithubBot-MultiBranches/venv/lib/python3.10/site-packages/flask/app.py", line 1525, in full_dispatch_request
    rv = self.handle_user_exception(e)
  File "/home/django/opensource/GithubBot-MultiBranches/venv/lib/python3.10/site-packages/flask/app.py", line 1523, in full_dispatch_request
    rv = self.dispatch_request()
  File "/home/django/opensource/GithubBot-MultiBranches/venv/lib/python3.10/site-packages/flask/app.py", line 1509, in dispatch_request
    return self.ensure_sync(self.view_functions[rule.endpoint])(**req.view_args)
  File "/home/django/opensource/GithubBot-MultiBranches/main.py", line 99, in general
    os.chdir(scriptpath)
NameError: name 'scriptpath' is not defined
[2022-09-01 23:06:36,657] 127.0.0.1 - - [01/Sep/2022 23:06:36] "[35m[1mPOST / HTTP/1.1[0m" 500 -
[2022-09-01 23:06:38,007] Executing: "/bin/git pull repository2 main --no-edit --no-commit".
[2022-09-01 23:06:40,696] Process "/bin/git pull repository2 main --no-edit --no-commit" returned (0)
[2022-09-01 23:06:40,696] Executing: "/bin/git push repository main".
[2022-09-01 23:06:43,101] Process "/bin/git push repository main" returned (0)
[2022-09-01 23:06:43,102] Exception on / [POST]
Traceback (most recent call last):
  File "/home/django/opensource/GithubBot-MultiBranches/venv/lib/python3.10/site-packages/flask/app.py", line 2077, in wsgi_app
    response = self.full_dispatch_request()
  File "/home/django/opensource/GithubBot-MultiBranches/venv/lib/python3.10/site-packages/flask/app.py", line 1525, in full_dispatch_request
    rv = self.handle_user_exception(e)
  File "/home/django/opensource/GithubBot-MultiBranches/venv/lib/python3.10/site-packages/flask/app.py", line 1523, in full_dispatch_request
    rv = self.dispatch_request()
  File "/home/django/opensource/GithubBot-MultiBranches/venv/lib/python3.10/site-packages/flask/app.py", line 1509, in dispatch_request
    return self.ensure_sync(self.view_functions[rule.endpoint])(**req.view_args)
  File "/home/django/opensource/GithubBot-MultiBranches/main.py", line 99, in general
    os.chdir(scriptpath)
NameError: name 'scriptpath' is not defined
[2022-09-01 23:06:43,103] 127.0.0.1 - - [01/Sep/2022 23:06:43] "[35m[1mPOST / HTTP/1.1[0m" 500 -
[2022-09-01 23:07:15,597] Directory '/home/django/localrepo' already exists!
[2022-09-01 23:07:15,601] Executing: "/bin/git init /home/django/localrepo -b main".
[2022-09-01 23:07:15,607] Process "/bin/git init /home/django/localrepo -b main" returned (0)
[2022-09-01 23:07:15,607] Executing: "/bin/git remote add repository git@github.com:GoodDay-lab/testing.git".
[2022-09-01 23:07:15,613] Process "/bin/git remote add repository git@github.com:GoodDay-lab/testing.git" returned (0)
[2022-09-01 23:07:15,613] Executing: "/bin/git pull repository main --rebase=true --no-edit --no-commit".
[2022-09-01 23:07:18,642] Process "/bin/git pull repository main --rebase=true --no-edit --no-commit" returned (0)
[2022-09-01 23:07:18,642] Executing: "/bin/git remote add repository2 git@github.com:GoodDay-lab/testing2.git".
[2022-09-01 23:07:18,647] Process "/bin/git remote add repository2 git@github.com:GoodDay-lab/testing2.git" returned (0)
[2022-09-01 23:07:18,647] Executing: "/bin/git pull repository2 main --rebase=true --no-edit --no-commit".
[2022-09-01 23:07:22,145] Process "/bin/git pull repository2 main --rebase=true --no-edit --no-commit" returned (0)
[2022-09-01 23:07:22,148]  * Running on http://127.0.0.1:9000 (Press CTRL+C to quit)
[2022-09-01 23:07:29,171] Executing: "/bin/git pull repository main --no-edit --no-commit".
[2022-09-01 23:07:32,267] Process "/bin/git pull repository main --no-edit --no-commit" returned (0)
[2022-09-01 23:07:32,268] Executing: "/bin/git push repository2 main".
[2022-09-01 23:07:35,058] Process "/bin/git push repository2 main" returned (0)
[2022-09-01 23:07:35,058] Exception on / [POST]
Traceback (most recent call last):
  File "/home/django/opensource/GithubBot-MultiBranches/venv/lib/python3.10/site-packages/flask/app.py", line 2077, in wsgi_app
    response = self.full_dispatch_request()
  File "/home/django/opensource/GithubBot-MultiBranches/venv/lib/python3.10/site-packages/flask/app.py", line 1525, in full_dispatch_request
    rv = self.handle_user_exception(e)
  File "/home/django/opensource/GithubBot-MultiBranches/venv/lib/python3.10/site-packages/flask/app.py", line 1523, in full_dispatch_request
    rv = self.dispatch_request()
  File "/home/django/opensource/GithubBot-MultiBranches/venv/lib/python3.10/site-packages/flask/app.py", line 1509, in dispatch_request
    return self.ensure_sync(self.view_functions[rule.endpoint])(**req.view_args)
  File "/home/django/opensource/GithubBot-MultiBranches/main.py", line 99, in general
    os.chdir(config_global["workdirectory"])
FileNotFoundError: [Errno 2] No such file or directory: '~'
[2022-09-01 23:07:35,061] 127.0.0.1 - - [01/Sep/2022 23:07:35] "[35m[1mPOST / HTTP/1.1[0m" 500 -
[2022-09-01 23:07:36,163] Executing: "/bin/git pull repository2 main --no-edit --no-commit".
[2022-09-01 23:07:38,989] Process "/bin/git pull repository2 main --no-edit --no-commit" returned (0)
[2022-09-01 23:07:38,990] Executing: "/bin/git push repository main".
[2022-09-01 23:07:41,488] Process "/bin/git push repository main" returned (0)
[2022-09-01 23:07:41,488] Exception on / [POST]
Traceback (most recent call last):
  File "/home/django/opensource/GithubBot-MultiBranches/venv/lib/python3.10/site-packages/flask/app.py", line 2077, in wsgi_app
    response = self.full_dispatch_request()
  File "/home/django/opensource/GithubBot-MultiBranches/venv/lib/python3.10/site-packages/flask/app.py", line 1525, in full_dispatch_request
    rv = self.handle_user_exception(e)
  File "/home/django/opensource/GithubBot-MultiBranches/venv/lib/python3.10/site-packages/flask/app.py", line 1523, in full_dispatch_request
    rv = self.dispatch_request()
  File "/home/django/opensource/GithubBot-MultiBranches/venv/lib/python3.10/site-packages/flask/app.py", line 1509, in dispatch_request
    return self.ensure_sync(self.view_functions[rule.endpoint])(**req.view_args)
  File "/home/django/opensource/GithubBot-MultiBranches/main.py", line 99, in general
    os.chdir(config_global["workdirectory"])
FileNotFoundError: [Errno 2] No such file or directory: '~'
[2022-09-01 23:07:41,489] 127.0.0.1 - - [01/Sep/2022 23:07:41] "[35m[1mPOST / HTTP/1.1[0m" 500 -
[2022-09-01 23:08:22,749] Directory '/home/django/localrepo' already exists!
[2022-09-01 23:08:22,752] Executing: "/bin/git init /home/django/localrepo -b main".
[2022-09-01 23:08:22,760] Process "/bin/git init /home/django/localrepo -b main" returned (0)
[2022-09-01 23:08:22,760] Executing: "/bin/git remote add repository git@github.com:GoodDay-lab/testing.git".
[2022-09-01 23:08:22,771] Process "/bin/git remote add repository git@github.com:GoodDay-lab/testing.git" returned (0)
[2022-09-01 23:08:22,771] Executing: "/bin/git pull repository main --rebase=true --no-edit --no-commit".
[2022-09-01 23:08:25,764] Process "/bin/git pull repository main --rebase=true --no-edit --no-commit" returned (0)
[2022-09-01 23:08:25,764] Executing: "/bin/git remote add repository2 git@github.com:GoodDay-lab/testing2.git".
[2022-09-01 23:08:25,768] Process "/bin/git remote add repository2 git@github.com:GoodDay-lab/testing2.git" returned (0)
[2022-09-01 23:08:25,768] Executing: "/bin/git pull repository2 main --rebase=true --no-edit --no-commit".
[2022-09-01 23:08:28,495] Process "/bin/git pull repository2 main --rebase=true --no-edit --no-commit" returned (0)
[2022-09-01 23:08:28,499]  * Running on http://127.0.0.1:9000 (Press CTRL+C to quit)
[2022-09-01 23:08:35,119] Executing: "/bin/git pull repository main --no-edit --no-commit".
[2022-09-01 23:08:38,216] Process "/bin/git pull repository main --no-edit --no-commit" returned (0)
[2022-09-01 23:08:38,216] Executing: "/bin/git push repository2 main".
[2022-09-01 23:08:40,936] Process "/bin/git push repository2 main" returned (0)
[2022-09-01 23:08:40,937] 127.0.0.1 - - [01/Sep/2022 23:08:40] "POST / HTTP/1.1" 200 -
[2022-09-01 23:08:42,603] Executing: "/bin/git pull repository2 main --no-edit --no-commit".
[2022-09-01 23:08:45,290] Process "/bin/git pull repository2 main --no-edit --no-commit" returned (0)
[2022-09-01 23:08:45,291] Executing: "/bin/git push repository main".
[2022-09-01 23:08:48,038] Process "/bin/git push repository main" returned (0)
[2022-09-01 23:08:48,038] 127.0.0.1 - - [01/Sep/2022 23:08:48] "POST / HTTP/1.1" 200 -
[2022-09-01 23:10:01,678] Executing: "/bin/git pull repository2 main --no-edit --no-commit".
[2022-09-01 23:10:04,754] Process "/bin/git pull repository2 main --no-edit --no-commit" returned (0)
[2022-09-01 23:10:04,754] Executing: "/bin/git push repository main".
[2022-09-01 23:10:07,989] Process "/bin/git push repository main" returned (0)
[2022-09-01 23:10:07,990] 127.0.0.1 - - [01/Sep/2022 23:10:07] "POST / HTTP/1.1" 200 -
[2022-09-01 23:10:08,979] Executing: "/bin/git pull repository main --no-edit --no-commit".
[2022-09-01 23:10:11,895] Process "/bin/git pull repository main --no-edit --no-commit" returned (0)
[2022-09-01 23:10:11,896] Executing: "/bin/git push repository2 main".
[2022-09-01 23:10:14,831] Process "/bin/git push repository2 main" returned (0)
[2022-09-01 23:10:14,832] 127.0.0.1 - - [01/Sep/2022 23:10:14] "POST / HTTP/1.1" 200 -
[2022-09-01 23:11:58,369] Executing: "/bin/git pull repository2 main --no-edit --no-commit".
[2022-09-01 23:12:01,016] Process "/bin/git pull repository2 main --no-edit --no-commit" returned (0)
[2022-09-01 23:12:01,016] Executing: "/bin/git push repository main".
[2022-09-01 23:12:03,791] Process "/bin/git push repository main" returned (0)
[2022-09-01 23:12:03,792] 127.0.0.1 - - [01/Sep/2022 23:12:03] "POST / HTTP/1.1" 200 -
[2022-09-01 23:13:16,346] Executing: "/bin/git pull repository2 main --no-edit --no-commit".
[2022-09-01 23:13:19,238] Process "/bin/git pull repository2 main --no-edit --no-commit" returned (0)
[2022-09-01 23:13:19,238] Executing: "/bin/git push repository main".
[2022-09-01 23:13:22,249] Process "/bin/git push repository main" returned (0)
[2022-09-01 23:13:22,250] 127.0.0.1 - - [01/Sep/2022 23:13:22] "POST / HTTP/1.1" 200 -
[2022-09-01 23:13:23,450] Executing: "/bin/git pull repository main --no-edit --no-commit".
[2022-09-01 23:13:26,652] Process "/bin/git pull repository main --no-edit --no-commit" returned (0)
[2022-09-01 23:13:26,653] Executing: "/bin/git push repository2 main".
[2022-09-01 23:13:29,442] Process "/bin/git push repository2 main" returned (0)
[2022-09-01 23:13:29,443] 127.0.0.1 - - [01/Sep/2022 23:13:29] "POST / HTTP/1.1" 200 -
[2022-09-02 00:36:48,215] Executing: "/bin/git init /tmp/localrepo -b main".
[2022-09-02 00:36:48,220] Process "/bin/git init /tmp/localrepo -b main" returned (0)
[2022-09-02 00:36:48,220] Executing: "/bin/git remote add repository git@github.com:GoodDay-lab/testing.git".
[2022-09-02 00:36:48,224] Process "/bin/git remote add repository git@github.com:GoodDay-lab/testing.git" returned (0)
[2022-09-02 00:36:48,224] Executing: "/bin/git pull repository main --rebase=true --no-edit --no-commit".
[2022-09-02 00:36:59,431] Process "/bin/git pull repository main --rebase=true --no-edit --no-commit" returned (0)
[2022-09-02 00:36:59,431] Executing: "/bin/git remote add repository2 git@github.com:GoodDay-lab/testing2.git".
[2022-09-02 00:36:59,436] Process "/bin/git remote add repository2 git@github.com:GoodDay-lab/testing2.git" returned (0)
[2022-09-02 00:36:59,436] Executing: "/bin/git pull repository2 main --rebase=true --no-edit --no-commit".
[2022-09-02 00:37:07,048] Process "/bin/git pull repository2 main --rebase=true --no-edit --no-commit" returned (0)
[2022-09-02 00:37:07,051]  * Running on http://127.0.0.1:9000 (Press CTRL+C to quit)
[2022-09-02 00:37:36,140] Executing: "/bin/git init /tmp/localrepo -b main".
[2022-09-02 00:37:36,144] Process "/bin/git init /tmp/localrepo -b main" returned (0)
[2022-09-02 00:37:36,144] Executing: "/bin/git remote add repository git@github.com:GoodDay-lab/testing.git".
[2022-09-02 00:37:36,147] Process "/bin/git remote add repository git@github.com:GoodDay-lab/testing.git" returned (0)
[2022-09-02 00:37:36,147] Executing: "/bin/git pull repository main --rebase=true --no-edit --no-commit".
[2022-09-02 00:37:45,986] Process "/bin/git pull repository main --rebase=true --no-edit --no-commit" returned (0)
[2022-09-02 00:37:45,986] Executing: "/bin/git remote add repository2 git@github.com:GoodDay-lab/testing2.git".
[2022-09-02 00:37:45,990] Process "/bin/git remote add repository2 git@github.com:GoodDay-lab/testing2.git" returned (0)
[2022-09-02 00:37:45,991] Executing: "/bin/git pull repository2 main --rebase=true --no-edit --no-commit".
[2022-09-02 00:37:53,267] Process "/bin/git pull repository2 main --rebase=true --no-edit --no-commit" returned (0)
[2022-09-02 00:37:53,272]  * Running on http://127.0.0.1:9000 (Press CTRL+C to quit)
[2022-09-02 00:39:38,770] Executing: "/bin/git init /tmp/localrepo -b main".
[2022-09-02 00:39:38,773] Process "/bin/git init /tmp/localrepo -b main" returned (0)
[2022-09-02 00:39:38,774] Executing: "/bin/git remote add repository git@github.com:GoodDay-lab/testing.git".
[2022-09-02 00:39:38,777] Process "/bin/git remote add repository git@github.com:GoodDay-lab/testing.git" returned (0)
[2022-09-02 00:39:38,777] Executing: "/bin/git pull repository main --rebase=true --no-edit --no-commit".
[2022-09-02 00:39:46,265] Process "/bin/git pull repository main --rebase=true --no-edit --no-commit" returned (0)
[2022-09-02 00:39:46,265] Executing: "/bin/git remote add repository2 git@github.com:GoodDay-lab/testing2.git".
[2022-09-02 00:39:46,268] Process "/bin/git remote add repository2 git@github.com:GoodDay-lab/testing2.git" returned (0)
[2022-09-02 00:39:46,269] Executing: "/bin/git pull repository2 main --rebase=true --no-edit --no-commit".
[2022-09-02 00:39:57,383] Process "/bin/git pull repository2 main --rebase=true --no-edit --no-commit" returned (0)
[2022-09-02 00:39:57,385]  * Running on http://127.0.0.1:9000 (Press CTRL+C to quit)
[2022-09-02 00:42:33,217] Executing: "/bin/git init /tmp/localrepo -b main".
[2022-09-02 00:42:33,222] Process "/bin/git init /tmp/localrepo -b main" returned (0)
[2022-09-02 00:42:33,222] Executing: "/bin/git remote add repository git@github.com:GoodDay-lab/testing.git".
[2022-09-02 00:42:33,226] Process "/bin/git remote add repository git@github.com:GoodDay-lab/testing.git" returned (0)
[2022-09-02 00:42:33,226] Executing: "/bin/git pull repository main --rebase=true --no-edit --no-commit".
[2022-09-02 00:42:41,943] Process "/bin/git pull repository main --rebase=true --no-edit --no-commit" returned (0)
[2022-09-02 00:42:41,943] Executing: "/bin/git remote add repository2 git@github.com:GoodDay-lab/testing2.git".
[2022-09-02 00:42:41,947] Process "/bin/git remote add repository2 git@github.com:GoodDay-lab/testing2.git" returned (0)
[2022-09-02 00:42:41,947] Executing: "/bin/git pull repository2 main --rebase=true --no-edit --no-commit".
[2022-09-02 00:42:48,411] Process "/bin/git pull repository2 main --rebase=true --no-edit --no-commit" returned (0)
[2022-09-02 00:47:22,520] Executing: "/bin/git init /tmp/localrepo -b main".
[2022-09-02 00:47:22,524] Process "/bin/git init /tmp/localrepo -b main" returned (0)
[2022-09-02 00:47:22,524] Executing: "/bin/git remote add repository git@github.com:GoodDay-lab/testing.git".
[2022-09-02 00:47:22,527] Process "/bin/git remote add repository git@github.com:GoodDay-lab/testing.git" returned (0)
[2022-09-02 00:47:22,527] Executing: "/bin/git pull repository main --rebase=true --no-edit --no-commit".
[2022-09-02 00:47:30,769] Process "/bin/git pull repository main --rebase=true --no-edit --no-commit" returned (0)
[2022-09-02 00:47:30,769] Executing: "/bin/git remote add repository2 git@github.com:GoodDay-lab/testing2.git".
[2022-09-02 00:47:30,774] Process "/bin/git remote add repository2 git@github.com:GoodDay-lab/testing2.git" returned (0)
[2022-09-02 00:47:30,774] Executing: "/bin/git pull repository2 main --rebase=true --no-edit --no-commit".
[2022-09-02 00:47:42,410] Process "/bin/git pull repository2 main --rebase=true --no-edit --no-commit" returned (0)
[2022-09-02 00:47:54,978] Executing: "/bin/git init /tmp/localrepo -b main".
[2022-09-02 00:47:54,984] Process "/bin/git init /tmp/localrepo -b main" returned (0)
[2022-09-02 00:47:54,984] Executing: "/bin/git remote add repository git@github.com:GoodDay-lab/testing.git".
[2022-09-02 00:47:54,989] Process "/bin/git remote add repository git@github.com:GoodDay-lab/testing.git" returned (0)
[2022-09-02 00:47:54,989] Executing: "/bin/git pull repository main --rebase=true --no-edit --no-commit".
[2022-09-02 00:48:03,761] Process "/bin/git pull repository main --rebase=true --no-edit --no-commit" returned (0)
[2022-09-02 00:48:03,761] Executing: "/bin/git remote add repository2 git@github.com:GoodDay-lab/testing2.git".
[2022-09-02 00:48:03,765] Process "/bin/git remote add repository2 git@github.com:GoodDay-lab/testing2.git" returned (0)
[2022-09-02 00:48:03,765] Executing: "/bin/git pull repository2 main --rebase=true --no-edit --no-commit".
[2022-09-02 00:48:09,901] Process "/bin/git pull repository2 main --rebase=true --no-edit --no-commit" returned (0)
[2022-09-02 00:48:09,904]  * Running on http://127.0.0.1:9000 (Press CTRL+C to quit)
[2022-09-02 00:50:49,269] Executing: "/bin/git init /tmp/localrepo -b main".
[2022-09-02 00:50:49,276] Process "/bin/git init /tmp/localrepo -b main" returned (0)
[2022-09-02 00:50:49,276] Executing: "/bin/git remote add repository git@github.com:GoodDay-lab/testing.git".
[2022-09-02 00:50:49,280] Process "/bin/git remote add repository git@github.com:GoodDay-lab/testing.git" returned (0)
[2022-09-02 00:50:49,281] Executing: "/bin/git pull repository main --rebase=true --no-edit --no-commit".
[2022-09-02 00:50:57,972] Process "/bin/git pull repository main --rebase=true --no-edit --no-commit" returned (0)
[2022-09-02 00:50:57,972] Executing: "/bin/git remote add repository2 git@github.com:GoodDay-lab/testing2.git".
[2022-09-02 00:50:57,975] Process "/bin/git remote add repository2 git@github.com:GoodDay-lab/testing2.git" returned (0)
[2022-09-02 00:50:57,975] Executing: "/bin/git pull repository2 main --rebase=true --no-edit --no-commit".
[2022-09-02 00:51:08,947] Process "/bin/git pull repository2 main --rebase=true --no-edit --no-commit" returned (0)
[2022-09-02 00:51:08,952]  * Running on http://127.0.0.1:9000 (Press CTRL+C to quit)
[2022-09-02 00:52:56,314] Executing: "/bin/git init /tmp/localrepo -b main".
[2022-09-02 00:52:56,320] Process "/bin/git init /tmp/localrepo -b main" returned (0)
[2022-09-02 00:52:56,320] Executing: "/bin/git remote add repository git@github.com:GoodDay-lab/testing.git".
[2022-09-02 00:52:56,325] Process "/bin/git remote add repository git@github.com:GoodDay-lab/testing.git" returned (0)
[2022-09-02 00:52:56,325] Executing: "/bin/git pull repository main --rebase=true --no-edit --no-commit".
[2022-09-02 00:53:01,078] Process "/bin/git pull repository main --rebase=true --no-edit --no-commit" failed.
[2022-09-02 00:53:01,079] Executing: "/bin/git remote add repository2 git@github.com:GoodDay-lab/testing2.git".
[2022-09-02 00:53:01,083] Process "/bin/git remote add repository2 git@github.com:GoodDay-lab/testing2.git" returned (0)
[2022-09-02 00:53:01,083] Executing: "/bin/git pull repository2 main --rebase=true --no-edit --no-commit".
[2022-09-02 00:53:42,339] Directory '/tmp/localrepo' already exists!
[2022-09-02 00:53:42,340] Executing: "/bin/git init /tmp/localrepo -b main".
[2022-09-02 00:53:42,344] Process "/bin/git init /tmp/localrepo -b main" returned (0)
[2022-09-02 00:53:42,344] Executing: "/bin/git remote add repository git@github.com:GoodDay-lab/testing.git".
[2022-09-02 00:53:42,347] Process "/bin/git remote add repository git@github.com:GoodDay-lab/testing.git" returned (0)
[2022-09-02 00:53:42,347] Executing: "/bin/git pull repository main --rebase=true --no-edit --no-commit".
[2022-09-02 00:53:51,347] Process "/bin/git pull repository main --rebase=true --no-edit --no-commit" returned (0)
[2022-09-02 00:53:51,347] Executing: "/bin/git remote add repository2 git@github.com:GoodDay-lab/testing2.git".
[2022-09-02 00:53:51,350] Process "/bin/git remote add repository2 git@github.com:GoodDay-lab/testing2.git" returned (0)
[2022-09-02 00:53:51,350] Executing: "/bin/git pull repository2 main --rebase=true --no-edit --no-commit".
[2022-09-02 00:53:59,146] Process "/bin/git pull repository2 main --rebase=true --no-edit --no-commit" returned (0)
[2022-09-02 00:53:59,151]  * Running on http://127.0.0.1:9000 (Press CTRL+C to quit)
[2022-09-02 00:54:41,147] Executing: "/bin/git init /tmp/localrepo -b main".
[2022-09-02 00:54:41,151] Process "/bin/git init /tmp/localrepo -b main" returned (0)
[2022-09-02 00:54:41,151] Executing: "/bin/git remote add repository git@github.com:GoodDay-lab/testing.git".
[2022-09-02 00:54:41,155] Process "/bin/git remote add repository git@github.com:GoodDay-lab/testing.git" returned (0)
[2022-09-02 00:54:41,155] Executing: "/bin/git pull repository main --rebase=true --no-edit --no-commit".
[2022-09-02 00:54:47,797] Process "/bin/git pull repository main --rebase=true --no-edit --no-commit" returned (0)
[2022-09-02 00:54:47,797] Executing: "/bin/git remote add repository2 git@github.com:GoodDay-lab/testing2.git".
[2022-09-02 00:54:47,802] Process "/bin/git remote add repository2 git@github.com:GoodDay-lab/testing2.git" returned (0)
[2022-09-02 00:54:47,802] Executing: "/bin/git pull repository2 main --rebase=true --no-edit --no-commit".
[2022-09-02 00:54:55,024] Process "/bin/git pull repository2 main --rebase=true --no-edit --no-commit" returned (0)
[2022-09-02 00:54:55,026]  * Running on http://127.0.0.1:9000 (Press CTRL+C to quit)
[2022-09-02 00:55:35,775] Executing: "/bin/git init /tmp/localrepo -b main".
[2022-09-02 00:55:35,781] Process "/bin/git init /tmp/localrepo -b main" returned (0)
[2022-09-02 00:55:35,781] Executing: "/bin/git remote add repository git@github.com:GoodDay-lab/testing.git".
[2022-09-02 00:55:35,784] Process "/bin/git remote add repository git@github.com:GoodDay-lab/testing.git" returned (0)
[2022-09-02 00:55:35,784] Executing: "/bin/git pull repository main --rebase=true --no-edit --no-commit".
[2022-09-02 00:55:42,294] Process "/bin/git pull repository main --rebase=true --no-edit --no-commit" returned (0)
[2022-09-02 00:55:42,294] Executing: "/bin/git remote add repository2 git@github.com:GoodDay-lab/testing2.git".
[2022-09-02 00:55:42,300] Process "/bin/git remote add repository2 git@github.com:GoodDay-lab/testing2.git" returned (0)
[2022-09-02 00:55:42,300] Executing: "/bin/git pull repository2 main --rebase=true --no-edit --no-commit".
[2022-09-02 00:55:52,574] Process "/bin/git pull repository2 main --rebase=true --no-edit --no-commit" returned (0)
[2022-09-02 00:55:52,579]  * Running on http://127.0.0.1:9000 (Press CTRL+C to quit)
[2022-09-02 00:56:12,659] 127.0.0.1 - - [02/Sep/2022 00:56:12] "[31m[1mGET / HTTP/1.1[0m" 405 -
[2022-09-02 00:56:12,715] 127.0.0.1 - - [02/Sep/2022 00:56:12] "[33mGET /favicon.ico HTTP/1.1[0m" 404 -
